Workbook

Sheet Лист1
A1: №№ | B1: ЖК | C1: Адрес объекта | D1: ID объекта | E1: IP-адрес(Контроллеры) | F1: Производитель | H1: порт | I1: IP-адрес (Теплосчётчики) | O1: Станция ХВС 1 | P1: Станция ХВС 2 | Q1: Некорректные данные от контроллеров | R1: Потребитель | S1: Ответственный
A2: 1 | B2: ЖК Саларьево-парк | C2: ул. Саларьевская д.9 | D2: 1 | E2: 172.32.20.32 | F2: Danfoss | G2: ECL310/210/mcx | H2: 502 | I2: 172.32.20.32 | J2: Теплосеть ТСРВ-042 (21:503) s/n 1901717 | K2: ГВС1,2 СВ а/с ТСРВ-024М (2:503) s/n 1901867 | L2: СО ЖЧ,НЖЧ,СВ клад ТСРВ-024М (1:503) s/n 1900039
A3: 2 | B3: ЖК Полярная 25 | C3: ул. Полярная д.25 корп.3 | D3: 2 | E3: 172.32.64.130 | F3: Danfoss | G3: ECL310/210/mcx | H3: 502
A4: 3 | B4: Тюмень | C4: ул. Полевая д.117 корп.3 | D4: 3 | E4: 172.32.21.138 | F4: Danfoss | G4: ECL4 | H4: 502
A5: 4 | B5: ЖК Кантемировская | C5: Муравска | D5: 4 | E5: 172.32.22.178 | F5: Signetics | G5: SMH4 | H5: 502
A6: 5 | B6: ЖК Саларьево-парк | C6: Адрес объекта | D6: 5 | E6: 172.32.20.23 | F6: Transformer | G6: SL | H6: 502 | I6: 172.32.20.24 | J6: Теплосеть ТСРВ-042 (20:502) s/n 1900944 | K6: ГВС ТСРВ-024М (21:502) s/n 1900922 | L6: СО ТСРВ-024М (22:502) s/n 1901296
A7: 6 | B7: ЖК Саларьево-парк | C7: ЖК Саларьево Парк, ул. Большое Понизовье д.3 | D7: 6 | E7: 172.32.20.12 | F7: Danfoss | G7: ECL310/210/mcx | H7: 502 | I7: 172.32.20.12 | J7: Теплосеть (ВИСТ 3:503) s/n 210879
A8: 7 | B8: ЖК Саларьево-парк | C8: ЖК Саларьево Парк, пр-т Магеллана д.33 | D8: 7 | E8: 172.32.20.2 | F8: Danfoss | G8: ECL310/210/mcx | H8: 502 | I8: 172.32.20.2 | J8: Теплосеть ТСРВ-042 (1:503) s/n 2001418 | K8: ГВС ТСРВ-042 (2:503) s/n 2101107 | L8: СО ЖЧ, СО НЖЧ, СВ клад ТСРВ-024М (3:503) s/n 2100048
A9: 8 | B9: ЖК Саларьево-парк | C9: ул. Большое Понизовье д.14 | D9: 8 | E9: 172.32.20.4 | F9: Danfoss | G9: ECL310/210/mcx | H9: 502 | I9: 172.32.20.4 | J9: Теплосеть ТСРВ-042 (21:503) s/n 2100018
A10: 9 | B10: ЖК Белая дача парк | C10: ул. Парковый микр. д.1 корп.6-7 | D10: 9 | E10: 172.32.75.2 | F10: Danfoss | G10: ECL310/210/mcx | H10: 502 | I10: 172.32.75.4 | J10: Теплосеть ТСРВ-042 (1:503) s/n 2100256 | K10: ГВС 1-2 ТСРВ-042 (2:504) s/n 2100989 | L10: СО Жч, Не Жч, Вентилячия ТСРВ-024М (3:504) s/n2100233
A11: 10 | B11: Тюмень | C11: ул. Полевая д.117 корп.5 | D11: 10 | E11: 172.32.21.142 | F11: Danfoss | G11: ECL310/210/mcx | H11: 502
A12: 11 | B12: Тюмень | C12: ул. Полевая д.117 корп.7 | D12: 11 | E12: 172.32.21.134 | F12: Danfoss | G12: ECL310/210/mcx | H12: 502
A13: 12 | B13: ЖК Измайловский лес | C13: ул. Реутовская д.20 | D13: 12 | E13: 172.32.64.194 | F13: Danfoss | G13: ECL310/210/mcx | H13: 502 | I13: 172.32.64.194 | J13: Теплосеть ТСРВ-042 (3:503) s/n 1900474 | K13: ГВС 1-2 ТСРВ-024М (2:503) s/n 2101344 | L13: СО ТСРВ-024М (1:503) s/n 2000013
A14: 13 | B14: Тюмень | C14: ул. Полевая д.117 корп.6 | D14: 13 | E14: 172.32.21.130 | F14: Danfoss | G14: ECL310/210/mcx | H14: 502
A15: 14 | B15: ЖК Сокольнический вал 1 | C15: ул. Сокольнический вал д.1 корп.1 | D15: 14 | E15: 172.32.22.2 | F15: Ridan | G15: Ridan | H15: 502
A16: 15 | B16: ЖК Мещерский лес | C16: ЖК Мещерский лес, ул. Домостроительная, д.2 | D16: 15 | E16: 172.32.23.130 | F16: Transformer | G16: SL | H16: 502 | I16: 172.32.23.160 | J16: Теплосеть ТСРВ-042 (1:502) s/n 2200378 | K16: ГВС1 и ГВС2 ТСРВ-042 (11:502) s/n 2200384 | L16: СО ЖЧ, СО НЖЧ, СВ НЖЧ ТСРВ-024M (12:502) s/n 2101203 | R16: ПИК-КОМФОРТ СИРИУС ООО
A17: 16 | B17: ЖК Бунинские луга | C17: ул. Александры Монаховой д.87 корп.2 | D17: 16 | E17: 172.32.21.66 | F17: Danfoss | G17: ECL310/210/mcx | H17: 502 | I17: 172.32.21.66 | J17: Теплосеть ТСРВ-042 (1:503) s/n 2101098 | K17: ГВС ТСРВ-042 (22:503) s/n 2101101 | L17: СВ, СО ЖЧ,НЖЧ ТСРВ-024M (23:503) s/n 2100398
A18: 17 | B18: ЖК Бунинские луга | C18: ул. Александры Монаховой д.87 корп.3 | D18: 17 | E18: 172.32.21.67 | F18: Danfoss | G18: ECL310/210/mcx | H18: 502 | I18: 172.32.21.67 | J18: Теплосеть ТСРВ-042 (1:503) s/n 1900453 | K18: ГВС ТСРВ-042 (22:503) s/n 1900447 | L18: СВ, СО ЖЧ,НЖЧ ТСРВ-024M (23:503) s/n 2200387
A19: 18 | B19: ЖК Бунинские луга | C19: ул. Александры Монаховой д.87 корп.1 | D19: 18 | E19: 172.32.21.68 | F19: Danfoss | G19: ECL310/210/mcx | H19: 502 | I19: 172.32.21.126 | J19: Теплосеть ТСРВ-042 (1:503) s/n 2101139 | K19: ГВС ТСРВ-042 (22:503) s/n 2101159 | L19: СВ, СО ЖЧ,НЖЧ ТСРВ-024M (23:503) s/n 2100028
A20: 19 | B20: ЖК Бунинские луга | C20: ул. Александры Монаховой д.87 корп.4 | D20: 19 | E20: 172.32.21.69 | F20: Danfoss | G20: ECL310/210/mcx | H20: 502 | I20: 172.32.21.69 | J20: Теплосеть ТСРВ-042 (1:503) s/n 2101135 | K20: ГВС ТСРВ-042 (22:503) s/n 2101147 | L20: СВ, СО ЖЧ,НЖЧ ТСРВ-024M (23:503) s/n 2101014
A21: 20 | B21: ЖК Бунинские луга | C21: ул. Александры Монаховой д.87 корп.5 | D21: 20 | E21: 172.32.21.70 | F21: Danfoss | G21: ECL310/210/mcx | H21: 502 | I21: 172.32.21.70 | J21: Теплосеть ТСРВ-042 (1:503) s/n 2101125 | K21: ГВС ТСРВ-042 (22:503) s/n 2001387 | L21: СВ, СО ЖЧ,НЖЧ ТСРВ-024M (23:503) s/n 2101125
A22: 21 | B22: ЖК Бунинские луга | C22: ул. Александры Монаховой д.87 корп.6 | D22: 21 | E22: 172.32.21.71 | F22: Danfoss | G22: ECL310/210/mcx | H22: 502 | I22: 172.32.21.71 | J22: Теплосеть ТСРВ-042 (1:503) s/n 2101105 | K22: ГВС ТСРВ-42 (22:503) s/n 2101092 | L22: СВ, СО ЖЧ,НЖЧ ТСРВ-024M (23:503) s/n 2101105
A23: 22 | B23: ЖК Мещерский лес | C23: ЖК Мещерский лес, Боровское шоссе, д.2А, корп.4 (корп.1.1) | D23: 22 | E23: 172.32.23.132 | F23: МЗТА | G23: MZTA:502 | H23: 502 | I23: 172.32.23.131 | J23: Теплосеть (ВИСТ 1:504) s/n 170245 | K23: ГВС2 (ВИСТ 3:503) s/n 170244 | L23: СО ЖЧ (ВИСТ 4:503) s/n 170246 | R23: ПИК-КОМФОРТ ООО
A24: 23 | B24: ЖК Мещерский лес | C24: ЖК Мещерский лес, Боровское шоссе, д.2, корп.2 (корп.6.1) | D24: 23 | E24: 172.32.23.133 | F24: Danfoss | G24: ECL310/210/mcx | H24: 502 | I24: 172.32.23.133 | J24: Теплосеть ТСРВ-042 (21:503) s/n 1901660 | K24: ГВС1, ГВС2 ТСРВ-024M (22:503) s/n 1900558 | L24: СВ, СО ЖЧ,НЖЧ ТСРВ-024M (23:503) s/n 1901999 | R24: ПИК-КОМФОРТ ООО
A25: 24 | B25: ЖК Мещерский лес | C25: ЖК Мещерский лес, ул. Домостроительная, д.14 | D25: 24 | E25: 172.32.23.141 | F25: Danfoss | G25: ECL310/210/mcx | H25: 502 | I25: 172.32.23.141 | J25: Теплосеть ТСРВ-042 (21:503) s/n 1901763 | K25: ГВС1, ГВС2 ТСРВ-024M (22:503) s/n 1901017 | L25: СВ, СО ЖЧ,НЖЧ ТСРВ-024M (23:503) s/n 1900208 | R25: ПИК-КОМФОРТ ООО
A26: 25 | B26: ЖК Мещерский лес | C26: ЖК Мещерский лес, Боровское шоссе, д.2 корп.3 (корп.5.2) | D26: 25 | E26: 172.32.23.143 | F26: Danfoss | G26: ECL310/210/mcx | H26: 502 | I26: 172.32.23.143 | J26: Теплосеть ТСРВ-042 (21:503) s/n 1901109 | K26: СВ, СО ЖЧ,НЖЧ ТСРВ-024M (22:503) s/n 1900512 | L26: ГВС1, ГВС2 ТСРВ-024M (23:503) s/n 1801826 | R26: ПИК-КОМФОРТ ООО
A27: 26 | B27: ЖК Ильинские луга | C27: ул. Заповедная, д.14 | D27: 26 | E27: 172.32.65.130 | F27: Danfoss | G27: ECL310/210/mcx | H27: 502 | I27: 172.32.65.171 | J27: Теплосеть ТСРВ-042 (1:503) s/n 2201001 | K27: ЖЧ СО, НЖЧ СО, ГВС ТСРВ-024м (2:503) s/n 2000128 | R27: ПИК-КОМФОРТ ЭЛИТСЕРВИС ООО
A28: 27 | B28: ЖК Бусиновский парк | C28: Бусиновский парк, корп.1.1 | D28: 27 | E28: 172.32.21.34 | F28: Danfoss | G28: ECL310/210/mcx | H28: 502 | R28: ПИК-КОМФОРТ СИРИУС ООО
A29: 28 | B29: ЖК Бусиновский парк | C29: Бусиновский парк, корп.2.1-2.2 | D29: 28 | E29: 172.32.21.36 | F29: Danfoss | G29: ECL310/210/mcx | H29: 502 | R29: ПИК-КОМФОРТ СИРИУС ООО
A30: 29 | B30: ЖК Жулебино парк | C30: ул. Летчика Ларюшина, д.4 | D30: 29 | E30: 172.32.68.2 | F30: Danfoss | G30: ECL310/210/mcx | H30: 502 | I30: 172.32.68.28 | J30: Теплосеть ТСРВ-042 (1:503) s/n 2200998 | K30: ГВС 1, ГВС 2 ТСРВ-042 (23:503) s/n 2200074 | L30: СО ЖЧ, СО НЖЧ, СВ ТСРВ-024м (22:503) s/n 2101124 | R30: ПИК-КОМФОРТ ЭЛИТСЕРВИС ООО
A31: 30 | B31: ЖК Жулебино парк | C31: ул. Летчика Ларюшина, д.4.1 (стр.11) | D31: 30 | E31: 172.32.68.3 | F31: Danfoss | G31: ECL310/210/mcx | H31: 502 | I31: 172.32.68.29 | J31: Теплосеть ТСРВ-042 (21:503) s/n 1801491 | K31: ГВС 1, ГВС 2 ТСРВ-042 (23:503) s/n 2101094 | L31: СО ЖЧ, СО НЖЧ, СВ ТСРВ-024м (22:503) s/n 2101364 | R31: ПИК-КОМФОРТ ЭЛИТСЕРВИС ООО
A32: 31 | B32: ЖК Люблинский парк | C32: ул. Люблинская, вл.72 корп.9 | D32: 31 | E32: 172.32.64.3 | F32: Danfoss | G32: ECL310/210/mcx | H32: 502
A33: 32 | B33: ЖК Дмитровский парк | C33: ЖК Дмитровский Парк, ул. Лобненская, д.13 корп.3 | D33: 32 | E33: 172.32.21.22 | F33: Danfoss | G33: ECL310/210/mcx | H33: 502 | I33: 172.32.21.23 | J33: Теплосеть (ВИСТ 21:502) s/n 210779 | K33: СО2 корп. 1 и 2 (ВИСТ 22:502) s/n 210783 | L33: Вент к. 1.3 и 1.2 (ВИСТ 23:502) s/n 210784 | M33: ГВС1 и ГВС2 (ВИСТ 24:502) s/n 210785 | N33: СО1 к.1.2 и СО ПОН к.1.2 (ВИСТ 25:502) s/n 210780 | O33: СО1 к.1.3 и СО ПОН к.1.3 (ВИСТ 26:502) s/n 210781 | P33: СО авт.ст. (ВИСТ 27:502) s/n 210782 | R33: ПИК-КОМФОРТ СМАРТ ООО
A34: 33 | B34: ЖК Дмитровский парк | C34: ЖК Дмитровский Парк, ул. Лобненская, д.13 корп.1 | D34: 33 | E34: 172.32.21.19 | F34: Danfoss | G34: ECL310/210/mcx | H34: 502 | I34: 172.32.21.19 | J34: Теплосеть ТСРВ-042 (1:503) | K34: СО 1з ТСРВ-024М (22:503) | L34: ГВС 1,ГВС2,СО 2з ТСРВ-024М (23:503) | R34: ПИК-КОМФОРТ ООО
A35: 34 | B35: ЖК Дмитровский парк | C35: ЖК Дмитровский Парк, ул. Лобненская, д.13 корп.2 (ИТП 2.1 секц.5) | D35: 34 | E35: 172.32.21.20 | F35: Danfoss | G35: ECL310/210/mcx | H35: 502 | I35: 172.32.21.20 | J35: Теплосеть (ВИСТ 11:503) s/n 200821 | K35: СО1 конт. 1 и 2 (ВИСТ 12:503) s/n 200824 | L35: СО2 конт. 1 и 2 (ВИСТ 13:503) s/n 200823 | M35: Тепло ПОН1, ПОН3, Вент.1 и 3 (ВИСТ 14:503) s/n 200822 | R35: ВИТЯЗЬ УК ООО
A36: 35 | B36: ЖК Дмитровский парк | C36: ЖК Дмитровский Парк, ул. Лобненская, д.13 корп.2 (ИТП 2.2 секц.6) | D36: 35 | E36: 172.32.21.21 | F36: Danfoss | G36: ECL310/210/mcx | H36: 502 | I36: 172.32.21.21 | J36: Теплосеть (ВИСТ 1:503) s/n 200825 | K36: СО1 конт.3 и 4 (ВИСТ 12:503) s/n 200827 | L36: СО2 конт. 1 и 2 (ВИСТ 13:503) s/n 200828 | M36: Тепло ПОН (ВИСТ 14:503) s/n 200829 | N36: ГВС1 конт.1 и 2 (ВИСТ 15:503) s/n 200830 | O36: ГВС2 конт.1 и 2 (ВИСТ 16:503) s/n 200831 | P36: СО1 конт.1 и 2 (ВИСТ 17:503) s/n 200826 | R36: ВИТЯЗЬ УК ООО
A37: 36 | B37: ЖК Волжский парк | C37: 1-й Грайвороновский пр-д д.11 корп.1 | D37: 36 | E37: 172.32.23.70 | F37: DVP | G37: DVP28SV | H37: 8000 | R37: ПИК-КОМФОРТ СИРИУС ООО
A38: 37 | B38: ЖК Мещерский лес | C38: ЖК Мещерский лес, Боровское шоссе, д.2А, корп.2 | D38: 37 | E38: 172.32.23.134 | F38: Transformer | G38: SL | H38: 502 | I38: 172.32.23.135 | J38: Теплосеть (ВИСТ 1:502) s/n 173197 | K38: ГВС1 и НЖЧ (ВИСТ 2:502) s/n 173412 | L38: ГВС2 (ВИСТ 3:503) s/n 173411 | M38: СО ЖЧ (ВИСТ 4:503) s/n 173413 | R38: ПИК-КОМФОРТ ООО
A39: 38 | B39: ЖК Красноказарменная 15 | C39: ул. Красноказарменная, д.15 корп.1.1 | D39: 38 | E39: 172.32.23.2 | F39: Danfoss | G39: ECL310/210/mcx | H39: 502 | R39: ПИК-КОМФОРТ СМАРТ ООО
A40: 39 | B40: ЖК Волжский парк | C40: 1-й Грайвороновский пр-д д.11 корп.2 | D40: 39 | E40: 172.32.23.72 | F40: DVP | G40: DVP28SV | H40: 8000 | R40: ПИК-КОМФОРТ СИРИУС ООО
...

Sheet Траблы с опросом контроллеров
A1: =Лист1!A1 -> №№ | B1: =Лист1!B1 -> ЖК | C1: =Лист1!C1 -> Адрес объекта | D1: =Лист1!D1 -> ID объекта | E1: =Лист1!E1 -> IP-адрес(Контроллеры) | F1: =Лист1!G1 -> 0 | G1: Проблемы с контроллерами
A2: =Лист1!A2 -> 1 | B2: =Лист1!B2 -> ЖК Саларьево-парк | C2: =Лист1!C2 -> ул. Саларьевская д.9 | D2: =Лист1!D2 -> 1 | E2: =Лист1!E2 -> 172.32.20.32 | F2: =Лист1!G2 -> ECL310/210/mcx
A3: =Лист1!A3 -> 2 | B3: =Лист1!B3 -> ЖК Полярная 25 | C3: =Лист1!C3 -> ул. Полярная д.25 корп.3 | D3: =Лист1!D3 -> 2 | E3: =Лист1!E3 -> 172.32.64.130 | F3: =Лист1!G3 -> ECL310/210/mcx
A4: =Лист1!A4 -> 3 | B4: =Лист1!B4 -> Тюмень | C4: =Лист1!C4 -> ул. Полевая д.117 корп.3 | D4: =Лист1!D4 -> 3 | E4: =Лист1!E4 -> 172.32.21.138 | F4: =Лист1!G4 -> ECL4
A5: =Лист1!A5 -> 4 | B5: =Лист1!B5 -> ЖК Кантемировская | C5: =Лист1!C5 -> Муравска | D5: =Лист1!D5 -> 4 | E5: =Лист1!E5 -> 172.32.22.178 | F5: =Лист1!G5 -> SMH4
A6: =Лист1!A6 -> 5 | B6: =Лист1!B6 -> ЖК Саларьево-парк | C6: =Лист1!C6 -> Адрес объекта | D6: =Лист1!D6 -> 5 | E6: =Лист1!E6 -> 172.32.20.23 | F6: =Лист1!G6 -> SL
A7: =Лист1!A7 -> 6 | B7: =Лист1!B7 -> ЖК Саларьево-парк | C7: =Лист1!C7 -> ЖК Саларьево Парк, ул. Большое Понизовье д.3 | D7: =Лист1!D7 -> 6 | E7: =Лист1!E7 -> 172.32.20.12 | F7: =Лист1!G7 -> ECL310/210/mcx
A8: =Лист1!A8 -> 7 | B8: =Лист1!B8 -> ЖК Саларьево-парк | C8: =Лист1!C8 -> ЖК Саларьево Парк, пр-т Магеллана д.33 | D8: =Лист1!D8 -> 7 | E8: =Лист1!E8 -> 172.32.20.2 | F8: =Лист1!G8 -> ECL310/210/mcx
A9: =Лист1!A9 -> 8 | B9: =Лист1!B9 -> ЖК Саларьево-парк | C9: =Лист1!C9 -> ул. Большое Понизовье д.14 | D9: =Лист1!D9 -> 8 | E9: =Лист1!E9 -> 172.32.20.4 | F9: =Лист1!G9 -> ECL310/210/mcx
A10: =Лист1!A10 -> 9 | B10: =Лист1!B10 -> ЖК Белая дача парк | C10: =Лист1!C10 -> ул. Парковый микр. д.1 корп.6-7 | D10: =Лист1!D10 -> 9 | E10: =Лист1!E10 -> 172.32.75.2 | F10: =Лист1!G10 -> ECL310/210/mcx
A11: =Лист1!A11 -> 10 | B11: =Лист1!B11 -> Тюмень | C11: =Лист1!C11 -> ул. Полевая д.117 корп.5 | D11: =Лист1!D11 -> 10 | E11: =Лист1!E11 -> 172.32.21.142 | F11: =Лист1!G11 -> ECL310/210/mcx
A12: =Лист1!A12 -> 11 | B12: =Лист1!B12 -> Тюмень | C12: =Лист1!C12 -> ул. Полевая д.117 корп.7 | D12: =Лист1!D12 -> 11 | E12: =Лист1!E12 -> 172.32.21.134 | F12: =Лист1!G12 -> ECL310/210/mcx
A13: =Лист1!A13 -> 12 | B13: =Лист1!B13 -> ЖК Измайловский лес | C13: =Лист1!C13 -> ул. Реутовская д.20 | D13: =Лист1!D13 -> 12 | E13: =Лист1!E13 -> 172.32.64.194 | F13: =Лист1!G13 -> ECL310/210/mcx
... A200: =Лист1!A200 -> 199 | B200: =Лист1!B200 -> ЖК Никольские луга | C200: =Лист1!C200 -> Варшавское шоссе 282 к1 | D200: =Лист1!D200 -> 199 | E200: =Лист1!E200 -> 172.32.70.194 | F200: =Лист1!G200 -> SL
